Time slot   0
ld_routine
Time slot   1
	Loaded a process at input/proc/p0s, PID: 1 PRIO: 130
Time slot   2
	CPU 3: Dispatched process  1
	Loaded a process at input/proc/s3, PID: 2 PRIO: 39
Time slot   3
	CPU 2: Dispatched process  2
liballoc:178
print_pgtbl:
 PDG=b44fb220b3b08710 P4g=b44fb220b3b09720 PUD=b44fb220b3b0a730 PMD=b44fb220b3b0b740
Time slot   4
	CPU 3: Put process  1 to run queue
	CPU 3: Dispatched process  1
	Loaded a process at input/proc/m1s, PID: 3 PRIO: 15
liballoc:178
print_pgtbl:
 PDG=b44fb220b3b0ef00 P4g=b44fb220b3b0ff10 PUD=b44fb220b3b10f20 PMD=b44fb220b3b11f30
Time slot   5
	CPU 2: Put process  2 to run queue
	CPU 2: Dispatched process  3
libfree:218
print_pgtbl:
 PDG=b44fb230b3b0ef00 P4g=b44fb230b3b0ff10 PUD=b44fb230b3b10f20 PMD=b44fb230b3b11f30
	CPU 1: Dispatched process  2
liballoc:178
print_pgtbl:
 PDG=b4cfc220b3b0ef00 P4g=b4cfc220b3b0ff10 PUD=b4cfc220b3b10f20 PMD=b4cfc220b3b11f30
Time slot   6
	CPU 3: Put process  1 to run queue
	CPU 3: Dispatched process  1
	Loaded a process at input/proc/s2, PID: 4 PRIO: 120
liballoc:178
print_pgtbl:
 PDG=b4cfc220b3b15960 P4g=b4cfc220b3b16970 PUD=b4cfc220b3b17980 PMD=b4cfc220b3b18990
liballoc:178
print_pgtbl:
 PDG=b44fb220b3b15960 P4g=b44fb220b3b16970 PUD=b44fb220b3b17980 PMD=b44fb220b3b18990
Time slot   7
libwrite:502
print_pgtbl:
 PDG=b44fb210b3b15960 P4g=b44fb210b3b16970 PUD=b44fb210b3b17980 PMD=b44fb210b3b18990
	CPU 1: Put process  2 to run queue
	CPU 1: Dispatched process  2
	CPU 2: Put process  3 to run queue
	CPU 2: Dispatched process  3
libfree:218
print_pgtbl:
 PDG=b4cfc230b3b15960 P4g=b4cfc230b3b16970 PUD=b4cfc230b3b17980 PMD=b4cfc230b3b18990
	CPU 0: Dispatched process  4
	Loaded a process at input/proc/m0s, PID: 5 PRIO: 120
Time slot   8
	CPU 3: Put process  1 to run queue
	CPU 3: Dispatched process  5
liballoc:178
print_pgtbl:
 PDG=b44fb220b3b1c170 P4g=b44fb220b3b1d180 PUD=b44fb220b3b1e190 PMD=b44fb220b3b1f1a0
liballoc:178
print_pgtbl:
 PDG=b4cfc220b3b1c170 P4g=b4cfc220b3b1d180 PUD=b4cfc220b3b1e190 PMD=b4cfc220b3b1f1a0
Time slot   9
	CPU 1: Put process  2 to run queue
	CPU 1: Dispatched process  2
	CPU 2: Put process  3 to run queue
	CPU 2: Dispatched process  3
libfree:218
print_pgtbl:
 PDG=b4cfc230b3b1c170 P4g=b4cfc230b3b1d180 PUD=b4cfc230b3b1e190 PMD=b4cfc230b3b1f1a0
	CPU 0: Put process  4 to run queue
	CPU 0: Dispatched process  4
	Loaded a process at input/proc/p1s, PID: 6 PRIO: 15
liballoc:178
print_pgtbl:
 PDG=b44fb220b3b22a10 P4g=b44fb220b3b23a20 PUD=b44fb220b3b24a30 PMD=b44fb220b3b25a40
Time slot  10
libfree:218
print_pgtbl:
 PDG=b4cfc230b3b22a10 P4g=b4cfc230b3b23a20 PUD=b4cfc230b3b24a30 PMD=b4cfc230b3b25a40
	CPU 3: Put process  5 to run queue
	CPU 3: Dispatched process  6
Time slot  11
	CPU 1: Put process  2 to run queue
	CPU 1: Dispatched process  2
	CPU 2: Processed  3 has finished
	CPU 2: Dispatched process  5
libfree:218
print_pgtbl:
 PDG=b4cfc230b3b22a10 P4g=b4cfc230b3b23a20 PUD=b4cfc230b3b24a30 PMD=b4cfc230b3b25a40
	CPU 0: Put process  4 to run queue
	CPU 0: Dispatched process  4
	Loaded a process at input/proc/s0, PID: 7 PRIO: 38
Time slot  12
	CPU 3: Put process  6 to run queue
	CPU 3: Dispatched process  6
liballoc:178
print_pgtbl:
 PDG=b4cfc220b3b29380 P4g=b4cfc220b3b2a390 PUD=b4cfc220b3b2b3a0 PMD=b4cfc220b3b2c3b0
Time slot  13
	CPU 1: Put process  2 to run queue
	CPU 1: Dispatched process  7
	CPU 2: Put process  5 to run queue
	CPU 2: Dispatched process  2
	CPU 0: Put process  4 to run queue
	CPU 0: Dispatched process  5
libwrite:502
print_pgtbl:
 PDG=b5cfe210b3b29380 P4g=b5cfe210b3b2a390 PUD=b5cfe210b3b2b3a0 PMD=b5cfe210b3b2c3b0
Time slot  14
	CPU 2: Processed  2 has finished
	CPU 2: Dispatched process  4
	CPU 3: Put process  6 to run queue
	CPU 3: Dispatched process  6
libwrite:502
print_pgtbl:
 PDG=b5cfe210b3b29380 P4g=b5cfe210b3b2a390 PUD=b5cfe210b3b2b3a0 PMD=b5cfe210b3b2c3b0
Time slot  15
	CPU 1: Put process  7 to run queue
	CPU 1: Dispatched process  7
	CPU 0: Processed  5 has finished
	CPU 0: Dispatched process  1
libread:426
Time slot  16
	CPU 2: Put process  4 to run queue
	CPU 2: Dispatched process  4
	CPU 3: Put process  6 to run queue
	CPU 3: Dispatched process  6
libwrite:502
print_pgtbl:
 PDG=b5cfe210b3b29380 P4g=b5cfe210b3b2a390 PUD=b5cfe210b3b2b3a0 PMD=b5cfe210b3b2c3b0
	Loaded a process at input/proc/s1, PID: 8 PRIO: 0
Time slot  17
	CPU 1: Put process  7 to run queue
	CPU 1: Dispatched process  8
	CPU 0: Put process  1 to run queue
	CPU 0: Dispatched process  7
Time slot  18
	CPU 3: Put process  6 to run queue
	CPU 3: Dispatched process  6
	CPU 2: Put process  4 to run queue
	CPU 2: Dispatched process  4
Time slot  19
	CPU 1: Put process  8 to run queue
	CPU 1: Dispatched process  8
	CPU 0: Put process  7 to run queue
	CPU 0: Dispatched process  7
Time slot  20
	CPU 3: Processed  6 has finished
	CPU 3: Dispatched process  1
libread:426
	CPU 2: Processed  4 has finished
	CPU 2 stopped
Time slot  21
	CPU 1: Put process  8 to run queue
	CPU 1: Dispatched process  8
libwrite:502
print_pgtbl:
 PDG=b44fb210b3b2fb90 P4g=b44fb210b3b30ba0 PUD=b44fb210b3b31bb0 PMD=b44fb210b3b32bc0
	CPU 0: Put process  7 to run queue
	CPU 0: Dispatched process  7
Time slot  22
	CPU 3: Put process  1 to run queue
	CPU 3: Dispatched process  1
libread:426
Time slot  23
	CPU 1: Put process  8 to run queue
	CPU 1: Dispatched process  8
	CPU 0: Put process  7 to run queue
	CPU 0: Dispatched process  7
Time slot  24
	CPU 1: Processed  8 has finished
	CPU 1 stopped
	CPU 3: Put process  1 to run queue
	CPU 3: Dispatched process  1
libfree:218
print_pgtbl:
 PDG=b44fb230b3b2fb90 P4g=b44fb230b3b30ba0 PUD=b44fb230b3b31bb0 PMD=b44fb230b3b32bc0
Time slot  25
	CPU 0: Put process  7 to run queue
	CPU 0: Dispatched process  7
Time slot  26
	CPU 3: Processed  1 has finished
	CPU 3 stopped
Time slot  27
	CPU 0: Put process  7 to run queue
	CPU 0: Dispatched process  7
Time slot  28
	CPU 0: Processed  7 has finished
	CPU 0 stopped
